[2024-10-24T20:38:08.115+0000] {taskinstance.py:1979} INFO - Dependencies all met for dep_context=non-requeueable deps ti=<TaskInstance: etl_queimadas.create_emr_cluster scheduled__2024-10-24T19:00:00+00:00 [queued]>
[2024-10-24T20:38:08.122+0000] {taskinstance.py:1979} INFO - Dependencies all met for dep_context=requeueable deps ti=<TaskInstance: etl_queimadas.create_emr_cluster scheduled__2024-10-24T19:00:00+00:00 [queued]>
[2024-10-24T20:38:08.123+0000] {taskinstance.py:2193} INFO - Starting attempt 1 of 1
[2024-10-24T20:38:08.134+0000] {taskinstance.py:2214} INFO - Executing <Task(PythonOperator): create_emr_cluster> on 2024-10-24 19:00:00+00:00
[2024-10-24T20:38:08.141+0000] {standard_task_runner.py:60} INFO - Started process 216 to run task
[2024-10-24T20:38:08.144+0000] {standard_task_runner.py:87} INFO - Running: ['***', 'tasks', 'run', 'etl_queimadas', 'create_emr_cluster', 'scheduled__2024-10-24T19:00:00+00:00', '--job-id', '107', '--raw', '--subdir', 'DAGS_FOLDER/dag_cria_emr.py', '--cfg-path', '/tmp/tmp_qhad6ib']
[2024-10-24T20:38:08.146+0000] {standard_task_runner.py:88} INFO - Job 107: Subtask create_emr_cluster
[2024-10-24T20:38:08.182+0000] {task_command.py:423} INFO - Running <TaskInstance: etl_queimadas.create_emr_cluster scheduled__2024-10-24T19:00:00+00:00 [running]> on host 622b1ac036ca
[2024-10-24T20:38:08.236+0000] {taskinstance.py:2510} INFO - Exporting env vars: AIRFLOW_CTX_DAG_OWNER='***' AIRFLOW_CTX_DAG_ID='etl_queimadas' AIRFLOW_CTX_TASK_ID='create_emr_cluster' AIRFLOW_CTX_EXECUTION_DATE='2024-10-24T19:00:00+00:00' AIRFLOW_CTX_TRY_NUMBER='1' AIRFLOW_CTX_DAG_RUN_ID='scheduled__2024-10-24T19:00:00+00:00'
[2024-10-24T20:38:08.238+0000] {taskinstance.py:2728} ERROR - Task failed with exception
Traceback (most recent call last):
  File "/home/airflow/.local/lib/python3.8/site-packages/airflow/models/taskinstance.py", line 444, in _execute_task
    result = _execute_callable(context=context, **execute_callable_kwargs)
  File "/home/airflow/.local/lib/python3.8/site-packages/airflow/models/taskinstance.py", line 414, in _execute_callable
    return execute_callable(context=context, **execute_callable_kwargs)
  File "/home/airflow/.local/lib/python3.8/site-packages/airflow/operators/python.py", line 200, in execute
    return_value = self.execute_callable()
  File "/home/airflow/.local/lib/python3.8/site-packages/airflow/operators/python.py", line 217, in execute_callable
    return self.python_callable(*self.op_args, **self.op_kwargs)
  File "/opt/airflow/dags/dag_cria_emr.py", line 10, in get_emr_client
    config.read_file(open(config_file_dir))
FileNotFoundError: [Errno 2] No such file or directory: '/opt/airflow/config/awes.cfg'
[2024-10-24T20:38:08.244+0000] {taskinstance.py:1149} INFO - Marking task as FAILED. dag_id=etl_queimadas, task_id=create_emr_cluster, execution_date=20241024T190000, start_date=20241024T203808, end_date=20241024T203808
[2024-10-24T20:38:08.256+0000] {standard_task_runner.py:107} ERROR - Failed to execute job 107 for task create_emr_cluster ([Errno 2] No such file or directory: '/opt/airflow/config/awes.cfg'; 216)
[2024-10-24T20:38:08.276+0000] {local_task_job_runner.py:234} INFO - Task exited with return code 1
[2024-10-24T20:38:08.290+0000] {taskinstance.py:3309} INFO - 0 downstream tasks scheduled from follow-on schedule check
