[2024-10-31T13:01:25.298+0000] {taskinstance.py:1979} INFO - Dependencies all met for dep_context=non-requeueable deps ti=<TaskInstance: etl_queimadas.add_step_job_gold_bioma manual__2024-10-31T13:00:59.480085+00:00 [queued]>
[2024-10-31T13:01:25.310+0000] {taskinstance.py:1979} INFO - Dependencies all met for dep_context=requeueable deps ti=<TaskInstance: etl_queimadas.add_step_job_gold_bioma manual__2024-10-31T13:00:59.480085+00:00 [queued]>
[2024-10-31T13:01:25.310+0000] {taskinstance.py:2193} INFO - Starting attempt 1 of 1
[2024-10-31T13:01:25.327+0000] {taskinstance.py:2214} INFO - Executing <Task(PythonOperator): add_step_job_gold_bioma> on 2024-10-31 13:00:59.480085+00:00
[2024-10-31T13:01:25.335+0000] {standard_task_runner.py:60} INFO - Started process 8404 to run task
[2024-10-31T13:01:25.338+0000] {standard_task_runner.py:87} INFO - Running: ['***', 'tasks', 'run', 'etl_queimadas', 'add_step_job_gold_bioma', 'manual__2024-10-31T13:00:59.480085+00:00', '--job-id', '252', '--raw', '--subdir', 'DAGS_FOLDER/dag_cria_emr.py', '--cfg-path', '/tmp/tmpwkjgri2b']
[2024-10-31T13:01:25.340+0000] {standard_task_runner.py:88} INFO - Job 252: Subtask add_step_job_gold_bioma
[2024-10-31T13:01:25.388+0000] {task_command.py:423} INFO - Running <TaskInstance: etl_queimadas.add_step_job_gold_bioma manual__2024-10-31T13:00:59.480085+00:00 [running]> on host 3f04bb9d0c09
[2024-10-31T13:01:25.474+0000] {taskinstance.py:2510} INFO - Exporting env vars: AIRFLOW_CTX_DAG_OWNER='***' AIRFLOW_CTX_DAG_ID='etl_queimadas' AIRFLOW_CTX_TASK_ID='add_step_job_gold_bioma' AIRFLOW_CTX_EXECUTION_DATE='2024-10-31T13:00:59.480085+00:00' AIRFLOW_CTX_TRY_NUMBER='1' AIRFLOW_CTX_DAG_RUN_ID='manual__2024-10-31T13:00:59.480085+00:00'
[2024-10-31T13:01:31.108+0000] {taskinstance.py:2728} ERROR - Task failed with exception
Traceback (most recent call last):
  File "/home/airflow/.local/lib/python3.8/site-packages/airflow/models/taskinstance.py", line 444, in _execute_task
    result = _execute_callable(context=context, **execute_callable_kwargs)
  File "/home/airflow/.local/lib/python3.8/site-packages/airflow/models/taskinstance.py", line 414, in _execute_callable
    return execute_callable(context=context, **execute_callable_kwargs)
  File "/home/airflow/.local/lib/python3.8/site-packages/airflow/operators/python.py", line 200, in execute
    return_value = self.execute_callable()
  File "/home/airflow/.local/lib/python3.8/site-packages/airflow/operators/python.py", line 217, in execute_callable
    return self.python_callable(*self.op_args, **self.op_kwargs)
  File "/opt/airflow/dags/dag_cria_emr.py", line 367, in _add_step_job_gold_bioma
    step_response = emr_client.add_job_flow_steps(
  File "/home/airflow/.local/lib/python3.8/site-packages/botocore/client.py", line 553, in _api_call
    return self._make_api_call(operation_name, kwargs)
  File "/home/airflow/.local/lib/python3.8/site-packages/botocore/client.py", line 1009, in _make_api_call
    raise error_class(parsed_response, operation_name)
botocore.exceptions.ClientError: An error occurred (ValidationException) when calling the AddJobFlowSteps operation: A job flow that is shutting down, terminated, or finished may not be modified.
[2024-10-31T13:01:31.116+0000] {taskinstance.py:1149} INFO - Marking task as FAILED. dag_id=etl_queimadas, task_id=add_step_job_gold_bioma, execution_date=20241031T130059, start_date=20241031T130125, end_date=20241031T130131
[2024-10-31T13:01:31.126+0000] {standard_task_runner.py:107} ERROR - Failed to execute job 252 for task add_step_job_gold_bioma (An error occurred (ValidationException) when calling the AddJobFlowSteps operation: A job flow that is shutting down, terminated, or finished may not be modified.; 8404)
[2024-10-31T13:01:31.140+0000] {local_task_job_runner.py:234} INFO - Task exited with return code 1
[2024-10-31T13:01:31.154+0000] {taskinstance.py:3309} INFO - 0 downstream tasks scheduled from follow-on schedule check
