[2024-10-25T21:42:39.927+0000] {taskinstance.py:1979} INFO - Dependencies all met for dep_context=non-requeueable deps ti=<TaskInstance: etl_queimadas.send_tweet manual__2024-10-25T21:42:38.289810+00:00 [queued]>
[2024-10-25T21:42:39.933+0000] {taskinstance.py:1979} INFO - Dependencies all met for dep_context=requeueable deps ti=<TaskInstance: etl_queimadas.send_tweet manual__2024-10-25T21:42:38.289810+00:00 [queued]>
[2024-10-25T21:42:39.933+0000] {taskinstance.py:2193} INFO - Starting attempt 1 of 1
[2024-10-25T21:42:39.942+0000] {taskinstance.py:2214} INFO - Executing <Task(PythonOperator): send_tweet> on 2024-10-25 21:42:38.289810+00:00
[2024-10-25T21:42:39.948+0000] {standard_task_runner.py:60} INFO - Started process 10218 to run task
[2024-10-25T21:42:39.950+0000] {standard_task_runner.py:87} INFO - Running: ['***', 'tasks', 'run', 'etl_queimadas', 'send_tweet', 'manual__2024-10-25T21:42:38.289810+00:00', '--job-id', '190', '--raw', '--subdir', 'DAGS_FOLDER/dag_cria_emr.py', '--cfg-path', '/tmp/tmpwpwtasxs']
[2024-10-25T21:42:39.951+0000] {standard_task_runner.py:88} INFO - Job 190: Subtask send_tweet
[2024-10-25T21:42:39.979+0000] {task_command.py:423} INFO - Running <TaskInstance: etl_queimadas.send_tweet manual__2024-10-25T21:42:38.289810+00:00 [running]> on host 622b1ac036ca
[2024-10-25T21:42:40.034+0000] {taskinstance.py:2510} INFO - Exporting env vars: AIRFLOW_CTX_DAG_OWNER='***' AIRFLOW_CTX_DAG_ID='etl_queimadas' AIRFLOW_CTX_TASK_ID='send_tweet' AIRFLOW_CTX_EXECUTION_DATE='2024-10-25T21:42:38.289810+00:00' AIRFLOW_CTX_TRY_NUMBER='1' AIRFLOW_CTX_DAG_RUN_ID='manual__2024-10-25T21:42:38.289810+00:00'
[2024-10-25T21:42:40.036+0000] {taskinstance.py:2728} ERROR - Task failed with exception
Traceback (most recent call last):
  File "/home/airflow/.local/lib/python3.8/site-packages/airflow/models/taskinstance.py", line 444, in _execute_task
    result = _execute_callable(context=context, **execute_callable_kwargs)
  File "/home/airflow/.local/lib/python3.8/site-packages/airflow/models/taskinstance.py", line 414, in _execute_callable
    return execute_callable(context=context, **execute_callable_kwargs)
  File "/home/airflow/.local/lib/python3.8/site-packages/airflow/operators/python.py", line 200, in execute
    return_value = self.execute_callable()
  File "/home/airflow/.local/lib/python3.8/site-packages/airflow/operators/python.py", line 217, in execute_callable
    return self.python_callable(*self.op_args, **self.op_kwargs)
  File "/opt/airflow/dags/dag_cria_emr.py", line 231, in _send_tweet
    bearer_token = config.get('TWITTER', 'BEARER_TOKEN')
  File "/usr/local/lib/python3.8/configparser.py", line 799, in get
    return self._interpolation.before_get(self, section, option, value,
  File "/usr/local/lib/python3.8/configparser.py", line 395, in before_get
    self._interpolate_some(parser, option, L, value, section, defaults, 1)
  File "/usr/local/lib/python3.8/configparser.py", line 442, in _interpolate_some
    raise InterpolationSyntaxError(
configparser.InterpolationSyntaxError: '%' must be followed by '%' or '(', found: '%2FPzuZwOaOmXP9f6m8Yl34s%3D8FMWgT6dZgxLfpkFegr7hVIiWr7BelUygf6W7XHezlHFQlw5JC'
[2024-10-25T21:42:40.042+0000] {taskinstance.py:1149} INFO - Marking task as FAILED. dag_id=etl_queimadas, task_id=send_tweet, execution_date=20241025T214238, start_date=20241025T214239, end_date=20241025T214240
[2024-10-25T21:42:40.049+0000] {standard_task_runner.py:107} ERROR - Failed to execute job 190 for task send_tweet ('%' must be followed by '%' or '(', found: '%2FPzuZwOaOmXP9f6m8Yl34s%3D8FMWgT6dZgxLfpkFegr7hVIiWr7BelUygf6W7XHezlHFQlw5JC'; 10218)
[2024-10-25T21:42:40.082+0000] {local_task_job_runner.py:234} INFO - Task exited with return code 1
[2024-10-25T21:42:40.093+0000] {taskinstance.py:3309} INFO - 0 downstream tasks scheduled from follow-on schedule check
