[2024-10-25T13:14:16.697+0000] {taskinstance.py:1979} INFO - Dependencies all met for dep_context=non-requeueable deps ti=<TaskInstance: etl_queimadas.create_emr_cluster manual__2024-10-25T13:14:15.137528+00:00 [queued]>
[2024-10-25T13:14:16.703+0000] {taskinstance.py:1979} INFO - Dependencies all met for dep_context=requeueable deps ti=<TaskInstance: etl_queimadas.create_emr_cluster manual__2024-10-25T13:14:15.137528+00:00 [queued]>
[2024-10-25T13:14:16.703+0000] {taskinstance.py:2193} INFO - Starting attempt 1 of 2
[2024-10-25T13:14:16.712+0000] {taskinstance.py:2214} INFO - Executing <Task(PythonOperator): create_emr_cluster> on 2024-10-25 13:14:15.137528+00:00
[2024-10-25T13:14:16.719+0000] {standard_task_runner.py:60} INFO - Started process 2039 to run task
[2024-10-25T13:14:16.721+0000] {standard_task_runner.py:87} INFO - Running: ['***', 'tasks', 'run', 'etl_queimadas', 'create_emr_cluster', 'manual__2024-10-25T13:14:15.137528+00:00', '--job-id', '117', '--raw', '--subdir', 'DAGS_FOLDER/dag_cria_emr.py', '--cfg-path', '/tmp/tmp4xzy5c_m']
[2024-10-25T13:14:16.722+0000] {standard_task_runner.py:88} INFO - Job 117: Subtask create_emr_cluster
[2024-10-25T13:14:16.750+0000] {task_command.py:423} INFO - Running <TaskInstance: etl_queimadas.create_emr_cluster manual__2024-10-25T13:14:15.137528+00:00 [running]> on host 622b1ac036ca
[2024-10-25T13:14:16.801+0000] {taskinstance.py:2510} INFO - Exporting env vars: AIRFLOW_CTX_DAG_OWNER='***' AIRFLOW_CTX_DAG_ID='etl_queimadas' AIRFLOW_CTX_TASK_ID='create_emr_cluster' AIRFLOW_CTX_EXECUTION_DATE='2024-10-25T13:14:15.137528+00:00' AIRFLOW_CTX_TRY_NUMBER='1' AIRFLOW_CTX_DAG_RUN_ID='manual__2024-10-25T13:14:15.137528+00:00'
[2024-10-25T13:14:16.855+0000] {taskinstance.py:2728} ERROR - Task failed with exception
Traceback (most recent call last):
  File "/home/airflow/.local/lib/python3.8/site-packages/airflow/models/taskinstance.py", line 444, in _execute_task
    result = _execute_callable(context=context, **execute_callable_kwargs)
  File "/home/airflow/.local/lib/python3.8/site-packages/airflow/models/taskinstance.py", line 414, in _execute_callable
    return execute_callable(context=context, **execute_callable_kwargs)
  File "/home/airflow/.local/lib/python3.8/site-packages/airflow/operators/python.py", line 200, in execute
    return_value = self.execute_callable()
  File "/home/airflow/.local/lib/python3.8/site-packages/airflow/operators/python.py", line 217, in execute_callable
    return self.python_callable(*self.op_args, **self.op_kwargs)
  File "/opt/airflow/dags/dag_cria_emr.py", line 51, in _create_emr_cluster
    aws_access_key_id=emr_client.meta.credentials.access_key,
AttributeError: 'ClientMeta' object has no attribute 'credentials'
[2024-10-25T13:14:16.860+0000] {taskinstance.py:1149} INFO - Marking task as UP_FOR_RETRY. dag_id=etl_queimadas, task_id=create_emr_cluster, execution_date=20241025T131415, start_date=20241025T131416, end_date=20241025T131416
[2024-10-25T13:14:16.867+0000] {standard_task_runner.py:107} ERROR - Failed to execute job 117 for task create_emr_cluster ('ClientMeta' object has no attribute 'credentials'; 2039)
[2024-10-25T13:14:16.892+0000] {local_task_job_runner.py:234} INFO - Task exited with return code 1
[2024-10-25T13:14:16.909+0000] {taskinstance.py:3309} INFO - 0 downstream tasks scheduled from follow-on schedule check
