[2024-10-31T13:01:25.282+0000] {taskinstance.py:1979} INFO - Dependencies all met for dep_context=non-requeueable deps ti=<TaskInstance: etl_queimadas.add_step_job_bronze manual__2024-10-31T13:00:59.480085+00:00 [queued]>
[2024-10-31T13:01:25.295+0000] {taskinstance.py:1979} INFO - Dependencies all met for dep_context=requeueable deps ti=<TaskInstance: etl_queimadas.add_step_job_bronze manual__2024-10-31T13:00:59.480085+00:00 [queued]>
[2024-10-31T13:01:25.295+0000] {taskinstance.py:2193} INFO - Starting attempt 1 of 1
[2024-10-31T13:01:25.314+0000] {taskinstance.py:2214} INFO - Executing <Task(PythonOperator): add_step_job_bronze> on 2024-10-31 13:00:59.480085+00:00
[2024-10-31T13:01:25.321+0000] {standard_task_runner.py:60} INFO - Started process 8403 to run task
[2024-10-31T13:01:25.324+0000] {standard_task_runner.py:87} INFO - Running: ['***', 'tasks', 'run', 'etl_queimadas', 'add_step_job_bronze', 'manual__2024-10-31T13:00:59.480085+00:00', '--job-id', '253', '--raw', '--subdir', 'DAGS_FOLDER/dag_cria_emr.py', '--cfg-path', '/tmp/tmpappa50cr']
[2024-10-31T13:01:25.326+0000] {standard_task_runner.py:88} INFO - Job 253: Subtask add_step_job_bronze
[2024-10-31T13:01:25.371+0000] {task_command.py:423} INFO - Running <TaskInstance: etl_queimadas.add_step_job_bronze manual__2024-10-31T13:00:59.480085+00:00 [running]> on host 3f04bb9d0c09
[2024-10-31T13:01:25.459+0000] {taskinstance.py:2510} INFO - Exporting env vars: AIRFLOW_CTX_DAG_OWNER='***' AIRFLOW_CTX_DAG_ID='etl_queimadas' AIRFLOW_CTX_TASK_ID='add_step_job_bronze' AIRFLOW_CTX_EXECUTION_DATE='2024-10-31T13:00:59.480085+00:00' AIRFLOW_CTX_TRY_NUMBER='1' AIRFLOW_CTX_DAG_RUN_ID='manual__2024-10-31T13:00:59.480085+00:00'
[2024-10-31T13:01:31.144+0000] {taskinstance.py:2728} ERROR - Task failed with exception
Traceback (most recent call last):
  File "/home/airflow/.local/lib/python3.8/site-packages/airflow/models/taskinstance.py", line 444, in _execute_task
    result = _execute_callable(context=context, **execute_callable_kwargs)
  File "/home/airflow/.local/lib/python3.8/site-packages/airflow/models/taskinstance.py", line 414, in _execute_callable
    return execute_callable(context=context, **execute_callable_kwargs)
  File "/home/airflow/.local/lib/python3.8/site-packages/airflow/operators/python.py", line 200, in execute
    return_value = self.execute_callable()
  File "/home/airflow/.local/lib/python3.8/site-packages/airflow/operators/python.py", line 217, in execute_callable
    return self.python_callable(*self.op_args, **self.op_kwargs)
  File "/opt/airflow/dags/dag_cria_emr.py", line 200, in _add_step_job_bronze
    step_response = emr_client.add_job_flow_steps(
  File "/home/airflow/.local/lib/python3.8/site-packages/botocore/client.py", line 553, in _api_call
    return self._make_api_call(operation_name, kwargs)
  File "/home/airflow/.local/lib/python3.8/site-packages/botocore/client.py", line 1009, in _make_api_call
    raise error_class(parsed_response, operation_name)
botocore.exceptions.ClientError: An error occurred (ValidationException) when calling the AddJobFlowSteps operation: A job flow that is shutting down, terminated, or finished may not be modified.
[2024-10-31T13:01:31.152+0000] {taskinstance.py:1149} INFO - Marking task as FAILED. dag_id=etl_queimadas, task_id=add_step_job_bronze, execution_date=20241031T130059, start_date=20241031T130125, end_date=20241031T130131
[2024-10-31T13:01:31.166+0000] {standard_task_runner.py:107} ERROR - Failed to execute job 253 for task add_step_job_bronze (An error occurred (ValidationException) when calling the AddJobFlowSteps operation: A job flow that is shutting down, terminated, or finished may not be modified.; 8403)
[2024-10-31T13:01:31.216+0000] {local_task_job_runner.py:234} INFO - Task exited with return code 1
[2024-10-31T13:01:31.229+0000] {taskinstance.py:3309} INFO - 0 downstream tasks scheduled from follow-on schedule check
